<?xml version="1.0" ?>

<robot name="rb1_robot">

    <!-- Define materials for visualization -->
    <material name="blue">
        <color rgba="0 0 1 1"/>
    </material>

    <material name="gray">
        <color rgba="0.40 0.40 0.40 1"/>
    </material>

    <material name="red">
        <color rgba="1 0 0 1"/>
    </material>

    <!-- Base footprint link -->
    <link name="base_footprint">
    </link>

    <!-- Joint connecting base_link and base_footprint -->
    <joint name="base_link_plate_joint" type="fixed">
        <origin rpy="0 0 0" xyz="0 0 0.15" />
        <parent link="base_footprint" />
        <child link="base_link" />
    </joint>

    <!-- Base link -->
    <link name="base_link">
        <!-- Visual representation of the base link -->
        <visual>
            <origin xyz="0 0 0" rpy="0 0 0"/>
            <geometry>
                <cylinder radius="0.25" length="0.3"/>
            </geometry>
            <material name="blue"/>
        </visual>
        <!-- Collision representation of the base link -->
        <collision>
            <origin xyz="0 0 0" rpy="0 0 0"/>
            <geometry>
                <cylinder radius="0.25" length="0.3"/>
            </geometry>
        </collision>
        <!-- Inertial properties of the base link -->
        <inertial>
            <mass value="20.5" />
            <origin xyz="0 0 0" rpy="0 0 0" />
            <inertia ixx="0.47406249999999994" ixy="0.0" ixz="0.0" iyy="0.47406249999999994" iyz="0.0" izz="0.640625" />
        </inertial>
    </link>

    <!-- Left wheel link -->
    <link name="left_wheel">
        <!-- Visual representation of the left wheel -->
        <visual>
            <origin xyz="0 0 0" rpy="-1.575 0 0"/>
            <geometry>
                <cylinder radius="0.025" length="0.03"/>
            </geometry>
            <material name="red"/>
        </visual>
        <!-- Collision representation of the left wheel -->
        <collision>
            <origin xyz="0 0 0" rpy="-1.575 0 0"/>
            <geometry>
                <cylinder radius="0.025" length="0.03"/>
            </geometry>
        </collision>
        <!-- Inertial properties of the left wheel -->
        <inertial>
            <mass value="1.5" />
            <origin xyz="0 0 0" rpy="-1.575 0 0" />
            <inertia ixx="0.00034687500000000007" ixy="0.0" ixz="0.0" iyy="0.00034687500000000007" iyz="0.0" izz="0.0004687500000000001" />
        </inertial>
    </link>

    <!-- Joint connecting base_link and left_wheel -->
    <joint name="base_link_left_wheel_joint" type="continuous">
        <axis xyz="0 1 0" rpy="0 0 0" />
        <origin rpy="0 0 0" xyz="0 0.2 -0.15" />
        <parent link="base_link" />
        <child link="left_wheel" />
    </joint>

    <!-- Right wheel link -->
    <link name="right_wheel">
        <!-- Visual representation of the right wheel -->
        <visual>
            <origin xyz="0 0 0" rpy="-1.575 0 0"/>
            <geometry>
                <cylinder radius="0.025" length="0.03"/>
            </geometry>
            <material name="red"/>
        </visual>
        <!-- Collision representation of the right wheel -->
        <collision>
            <origin xyz="0 0 0" rpy="-1.575 0 0"/>
            <geometry>
                <cylinder radius="0.025" length="0.03"/>
            </geometry>
        </collision>
        <!-- Inertial properties of the right wheel -->
        <inertial>
            <mass value="1.5" />
            <origin xyz="0 0 0" rpy="-1.575 0 0" />
            <inertia ixx="0.00034687500000000007" ixy="0.0" ixz="0.0" iyy="0.00034687500000000007" iyz="0.0" izz="0.0004687500000000001" />
        </inertial>
    </link>

    <!-- Joint connecting base_link and right_wheel -->
    <joint name="base_link_right_wheel_joint" type="continuous">
        <axis xyz="0 1 0" rpy="0 0 0" />
        <origin rpy="0 0 0" xyz="0 -0.2 -0.15" />
        <parent link="base_link" />
        <child link="right_wheel" />
    </joint>

    <!-- Link representing the front caster wheel -->
    <link name="front_caster">
        <visual>
            <origin xyz="0 0 0" rpy="0 0 0" />
            <geometry>
                <sphere radius="0.025" />
            </geometry>
            <material name="gray"/>
        </visual>
        <collision>
            <origin xyz="0 0 0" rpy="0 0 0" />
            <contact_coefficients mu="0.0" kp="0.0" kd="0.0" />
            <geometry>
                <sphere radius="0.025" />
            </geometry>
        </collision>
        <inertial>
            <mass value="0.5" />
            <origin xyz="0 0 0" rpy="0 0 0" />
            <inertia ixx="0.00012500000000000003" ixy="0.0" ixz="0.0" iyy="0.00012500000000000003" iyz="0.0" izz="0.00012500000000000003" />
        </inertial>
    </link>

    <!-- Joint connecting base_link and front_caster -->
    <joint name="base_link_front_caster_joint" type="fixed">
        <parent link="base_link"/>
        <child link="front_caster"/>
        <origin xyz="0.1 0.0 -0.15" rpy="0 0 0"/>
    </joint>

    <!-- Link representing the back caster wheel -->
    <link name="back_caster">
        <visual>
            <origin xyz="0 0 0" rpy="0 0 0" />
            <geometry>
                <sphere radius="0.025" />
            </geometry>
            <material name="gray"/>
        </visual>
        <collision>
            <origin xyz="0 0 0" rpy="0 0 0" />
            <contact_coefficients mu="0.0" kp="0.0" kd="0.0" />
            <geometry>
                <sphere radius="0.025" />
            </geometry>
        </collision>
        <inertial>
            <mass value="0.5" />
            <origin xyz="0 0 0" rpy="0 0 0" />
            <inertia ixx="0.00012500000000000003" ixy="0.0" ixz="0.0" iyy="0.00012500000000000003" iyz="0.0" izz="0.00012500000000000003" />
        </inertial>
    </link>

    <!-- Joint connecting base_link and back_caster -->
    <joint name="base_link_back_caster_joint" type="fixed">
        <parent link="base_link"/>
        <child link="back_caster"/>
        <origin xyz="-0.1 0.0 -0.15" rpy="0 0 0"/>
    </joint>

    <!-- Link representing the laser -->
    <link name="front_laser">
    </link>

    <!-- Joint connecting base_link and front_laser -->
    <joint name="base_link_front_laser_joint" type="fixed">
        <origin rpy="3.14 0 0" xyz="0.25 0 0.075" />
        <parent link="base_link" />
        <child link="front_laser" />
    </joint>

    <!-- Specify Gazebo color for the base_link -->
    <gazebo reference="base_link">
        <visual>
            <material> <!-- Black -->
                <ambient>0 0 0 1</ambient>
                <diffuse>0 0 0 1</diffuse>
                <specular>0 0 0 1</specular>
                <emissive>0 0 0 1</emissive>
            </material>
        </visual>
    </gazebo>

    <!-- Gazebo friction and material properties for left_wheel -->
    <gazebo reference="left_wheel">
        <collision>
            <surface>
                <friction>
                    <ode>
                        <mu>5.0</mu>
                        <mu2>0.5</mu2>
                    </ode>
                </friction>
            </surface>
        </collision>
    </gazebo>

    <!-- Gazebo friction and material properties for right_wheel -->
    <gazebo reference="right_wheel">
        <collision>
            <surface>
                <friction>
                    <ode>
                        <mu>5.0</mu>
                        <mu2>0.5</mu2>
                    </ode>
                </friction>
            </surface>
        </collision>
    </gazebo>

    <!-- Gazebo friction and material properties for front_caster -->
    <gazebo reference="front_caster">
        <collision>
            <surface>
                <friction>
                    <ode>
                        <mu>5.0</mu>
                        <mu2>0.5</mu2>
                    </ode>
                </friction>
            </surface>
        </collision>
    </gazebo>

    <!-- Gazebo friction and material properties for back_caster -->
    <gazebo reference="back_caster">
        <collision>
            <surface>
                <friction>
                    <ode>
                        <mu>5.0</mu>
                        <mu2>0.5</mu2>
                    </ode>
                </friction>
            </surface>
        </collision>
    </gazebo>

    <!-- Gazebo plugin for differential drive controller -->

    <!-- Differential Drive Plugin -->
    <gazebo>
        <plugin
            filename="libignition-gazebo-diff-drive-system.so"
            name="ignition::gazebo::systems::DiffDrive">
            <left_joint>base_link_left_wheel_joint</left_joint>
            <right_joint>base_link_right_wheel_joint</right_joint>
            <wheel_separation>0.4</wheel_separation>
            <wheel_radius>0.025</wheel_radius>
            <odom_publish_frequency>20</odom_publish_frequency>
            <topic>cmd_vel</topic>
            <odom_topic>odom</odom_topic>
            <tf_topic>tf</tf_topic>
            <frame_id>odom</frame_id>
            <child_frame_id>base_footprint</child_frame_id>
        </plugin>
    </gazebo>

    <!-- Gazebo configuration for the front laser sensor -->

    <gazebo>
        <plugin
        filename="libignition-gazebo-sensors-system"
        name="ignition::gazebo::systems::Sensors">
        <!-- use ogre2 if ogre v2.x is installed, otherwise use ogre -->
        <render_engine>ogre2</render_engine>
        </plugin>
    </gazebo>
    <gazebo reference="front_laser">
        <sensor type="gpu_lidar" name="head_hokuyo_sensor">
            <pose relative_to='lidar_frame'>0 0 0 0 0 0</pose>
            <always_on>1</always_on>
            <visualize>true</visualize>
            <update_rate>20</update_rate>
            <topic>/scan</topic>
            <ray>
                <scan>
                    <horizontal>
                        <samples>720</samples>
                        <resolution>1</resolution>
                        <min_angle>-1.570796</min_angle>
                        <max_angle>1.570796</max_angle>
                    </horizontal>
                </scan>
                <range>
                    <min>0.20</min>
                    <max>10.0</max>
                    <resolution>0.01</resolution>
                </range>
                <noise>
                    <type>gaussian</type>
                    <mean>0.0</mean>
                    <stddev>0.01</stddev>
                </noise>
            </ray>
        </sensor>
    </gazebo>

</robot>